Workbook
Name Slicer_Month: #N/A
Name Slicer_Outlet: #N/A

Sheet RawData
A1: Month | B1: Outlet | C1: Region | D1: Outlet Type | E1: Budget Sales (RM) | F1: Actual Sales (RM) | G1: Opening Stock (RM) | H1: Purchases (RM) | I1: Transfer In (RM) | J1: Transfer Out (RM) | K1: Closing Stock (RM) | L1: Wastage Cost (RM) | M1: System Stock Value (RM) | N1: Physical Stock Value (RM) | O1: Transactions
A2: 46023 | B2: Outlet A | C2: Central | D2: Restaurant | E2: 155000 | F2: 152000 | G2: 28000 | H2: 52000 | I2: 1500 | J2: 800 | K2: 31500 | L2: 1900 | M2: 31500 | N2: 31250 | O2: 13200
A3: 46054 | B3: Outlet A | C3: Central | D3: Restaurant | E3: 160000 | F3: 160420 | G3: 31500 | H3: 53500 | I3: 1200 | J3: 700 | K3: 33700 | L3: 1950 | M3: 33700 | N3: 33450 | O3: 13800
A4: 46082 | B4: Outlet A | C4: Central | D4: Restaurant | E4: 175000 | F4: 180450 | G4: 33700 | H4: 56000 | I4: 1000 | J4: 900 | K4: 34800 | L4: 2165 | M4: 34800 | N4: 34520 | O4: 14900
A5: 46023 | B5: Outlet B | C5: North | D5: Restaurant | E5: 175000 | F5: 158000 | G5: 30000 | H5: 49000 | I5: 1000 | J5: 500 | K5: 29000 | L5: 3000 | M5: 29000 | N5: 28150 | O5: 14000
A6: 46054 | B6: Outlet B | C6: North | D6: Restaurant | E6: 180000 | F6: 160420 | G6: 29000 | H6: 52000 | I6: 1200 | J6: 700 | K6: 31000 | L6: 3040 | M6: 31000 | N6: 30120 | O6: 14300
A7: 46082 | B7: Outlet B | C7: North | D7: Restaurant | E7: 185000 | F7: 165230 | G7: 31000 | H7: 59000 | I7: 900 | J7: 600 | K7: 33500 | L7: 5122 | M7: 33500 | N7: 32560 | O7: 14550
A8: 46023 | B8: Outlet C | C8: South | D8: Restaurant | E8: 190000 | F8: 189550 | G8: 34000 | H8: 61000 | I8: 1800 | J8: 900 | K8: 36000 | L8: 2654 | M8: 36000 | N8: 35680 | O8: 16000
A9: 46054 | B9: Outlet C | C9: South | D9: Restaurant | E9: 200000 | F9: 201760 | G9: 36000 | H9: 64000 | I9: 1500 | J9: 800 | K9: 38800 | L9: 2825 | M9: 38800 | N9: 38450 | O9: 16800
A10: 46082 | B10: Outlet C | C10: South | D10: Restaurant | E10: 205000 | F10: 210540 | G10: 38800 | H10: 66000 | I10: 1200 | J10: 1000 | K10: 40200 | L10: 2948 | M10: 40200 | N10: 39840 | O10: 17400
A11: 46023 | B11: Outlet D | C11: Central | D11: Restaurant | E11: 165000 | F11: 162350 | G11: 29000 | H11: 53000 | I11: 1000 | J11: 800 | K11: 31000 | L11: 3200 | M11: 31000 | N11: 30350 | O11: 13700
A12: 46054 | B12: Outlet D | C12: Central | D12: Restaurant | E12: 170000 | F12: 170820 | G12: 31000 | H12: 56000 | I12: 1100 | J12: 700 | K12: 33000 | L12: 3500 | M12: 33000 | N12: 32280 | O12: 14400
A13: 46082 | B13: Outlet D | C13: Central | D13: Restaurant | E13: 175000 | F13: 186540 | G13: 33000 | H13: 62000 | I13: 900 | J13: 800 | K13: 34500 | L13: 5037 | M13: 34500 | N13: 33775 | O13: 15300
... A16: 46082 | B16: Outlet E | C16: East | D16: Restaurant | E16: 190000 | F16: 195460 | G16: 35000 | H16: 61000 | I16: 1000 | J16: 900 | K16: 36200 | L16: 2140 | M16: 36200 | N16: 35950 | O16: 16000

Sheet Analysis
A1: Month | B1: Outlet | C1: Actual Sales (RM) | D1: Expected Sales (RM) | E1: Purchases (RM) | F1: Wastage Cost (RM) | G1: Transactions | H1: Sales Variance (RM) | I1: Sales Variance % | J1: COGS / Stock Usage (RM) | K1: Food Cost % | L1: Food Cost Target % | M1: Food Cost Variance (pp) | N1: Stock Variance (RM) | O1: Stock Variance % | P1: Wastage % | Q1: Avg Transaction Value (RM)
A2: =RawData!A2 -> 46023 | B2: =RawData!B2 -> Outlet A | C2: =RawData!F2 -> 152000 | D2: =RawData!E2 -> 155000 | E2: 52000 | F2: 1900 | G2: 13200 | H2: =C2-D2 -> -3000 | I2: =IFERROR(H2/D2,0) -> -0.019354839 | J2: =RawData!G2+RawData!H2+RawData!I2-RawData!J2-RawData!K2 -> 49200 | K2: =IFERROR(J2/C2,0) -> 0.32368421 | L2: =32% -> 0.32 | M2: =K2-L2 -> 0.0036842105 | N2: =RawData!N2-RawData!M2 -> -250 | O2: =IFERROR(N2/RawData!M2,0) -> -0.0079365079 | P2: =IFERROR(RawData!L2/C2,0) -> 0.0125 | Q2: =IFERROR(C2/RawData!O2,0) -> 11.515152
A3: =RawData!A3 -> 46054 | B3: =RawData!B3 -> Outlet A | C3: =RawData!F3 -> 160420 | D3: =RawData!E3 -> 160000 | E3: 53500 | F3: 1950 | G3: 13800 | H3: =C3-D3 -> 420 | I3: =IFERROR(H3/D3,0) -> 0.002625 | J3: =RawData!G3+RawData!H3+RawData!I3-RawData!J3-RawData!K3 -> 51800 | K3: =IFERROR(J3/C3,0) -> 0.32290238 | L3: =32% -> 0.32 | M3: =K3-L3 -> 0.0029023812 | N3: =RawData!N3-RawData!M3 -> -250 | O3: =IFERROR(N3/RawData!M3,0) -> -0.0074183976 | P3: =IFERROR(RawData!L3/C3,0) -> 0.012155592 | Q3: =IFERROR(C3/RawData!O3,0) -> 11.624638
A4: =RawData!A4 -> 46082 | B4: =RawData!B4 -> Outlet A | C4: =RawData!F4 -> 180450 | D4: =RawData!E4 -> 175000 | E4: 56000 | F4: 2165 | G4: 14900 | H4: =C4-D4 -> 5450 | I4: =IFERROR(H4/D4,0) -> 0.031142857 | J4: =RawData!G4+RawData!H4+RawData!I4-RawData!J4-RawData!K4 -> 55000 | K4: =IFERROR(J4/C4,0) -> 0.30479357 | L4: =32% -> 0.32 | M4: =K4-L4 -> -0.015206428 | N4: =RawData!N4-RawData!M4 -> -280 | O4: =IFERROR(N4/RawData!M4,0) -> -0.008045977 | P4: =IFERROR(RawData!L4/C4,0) -> 0.011997783 | Q4: =IFERROR(C4/RawData!O4,0) -> 12.110738
A5: =RawData!A5 -> 46023 | B5: =RawData!B5 -> Outlet B | C5: =RawData!F5 -> 158000 | D5: =RawData!E5 -> 175000 | E5: 49000 | F5: 3000 | G5: 14000 | H5: =C5-D5 -> -17000 | I5: =IFERROR(H5/D5,0) -> -0.097142857 | J5: =RawData!G5+RawData!H5+RawData!I5-RawData!J5-RawData!K5 -> 50500 | K5: =IFERROR(J5/C5,0) -> 0.31962025 | L5: =32% -> 0.32 | M5: =K5-L5 -> -0.00037974684 | N5: =RawData!N5-RawData!M5 -> -850 | O5: =IFERROR(N5/RawData!M5,0) -> -0.029310345 | P5: =IFERROR(RawData!L5/C5,0) -> 0.018987342 | Q5: =IFERROR(C5/RawData!O5,0) -> 11.285714
A6: =RawData!A6 -> 46054 | B6: =RawData!B6 -> Outlet B | C6: =RawData!F6 -> 160420 | D6: =RawData!E6 -> 180000 | E6: 52000 | F6: 3040 | G6: 14300 | H6: =C6-D6 -> -19580 | I6: =IFERROR(H6/D6,0) -> -0.10877778 | J6: =RawData!G6+RawData!H6+RawData!I6-RawData!J6-RawData!K6 -> 50500 | K6: =IFERROR(J6/C6,0) -> 0.31479865 | L6: =32% -> 0.32 | M6: =K6-L6 -> -0.0052013465 | N6: =RawData!N6-RawData!M6 -> -880 | O6: =IFERROR(N6/RawData!M6,0) -> -0.028387097 | P6: =IFERROR(RawData!L6/C6,0) -> 0.018950256 | Q6: =IFERROR(C6/RawData!O6,0) -> 11.218182
A7: =RawData!A7 -> 46082 | B7: =RawData!B7 -> Outlet B | C7: =RawData!F7 -> 165230 | D7: =RawData!E7 -> 185000 | E7: 59000 | F7: 5122 | G7: 14550 | H7: =C7-D7 -> -19770 | I7: =IFERROR(H7/D7,0) -> -0.10686486 | J7: =RawData!G7+RawData!H7+RawData!I7-RawData!J7-RawData!K7 -> 56800 | K7: =IFERROR(J7/C7,0) -> 0.34376324 | L7: =32% -> 0.32 | M7: =K7-L7 -> 0.023763239 | N7: =RawData!N7-RawData!M7 -> -940 | O7: =IFERROR(N7/RawData!M7,0) -> -0.028059701 | P7: =IFERROR(RawData!L7/C7,0) -> 0.030999213 | Q7: =IFERROR(C7/RawData!O7,0) -> 11.356014
A8: =RawData!A8 -> 46023 | B8: =RawData!B8 -> Outlet C | C8: =RawData!F8 -> 189550 | D8: =RawData!E8 -> 190000 | E8: 61000 | F8: 2654 | G8: 16000 | H8: =C8-D8 -> -450 | I8: =IFERROR(H8/D8,0) -> -0.0023684211 | J8: =RawData!G8+RawData!H8+RawData!I8-RawData!J8-RawData!K8 -> 59900 | K8: =IFERROR(J8/C8,0) -> 0.31601161 | L8: =32% -> 0.32 | M8: =K8-L8 -> -0.0039883936 | N8: =RawData!N8-RawData!M8 -> -320 | O8: =IFERROR(N8/RawData!M8,0) -> -0.0088888889 | P8: =IFERROR(RawData!L8/C8,0) -> 0.014001583 | Q8: =IFERROR(C8/RawData!O8,0) -> 11.846875
A9: =RawData!A9 -> 46054 | B9: =RawData!B9 -> Outlet C | C9: =RawData!F9 -> 201760 | D9: =RawData!E9 -> 200000 | E9: 64000 | F9: 2825 | G9: 16800 | H9: =C9-D9 -> 1760 | I9: =IFERROR(H9/D9,0) -> 0.0088 | J9: =RawData!G9+RawData!H9+RawData!I9-RawData!J9-RawData!K9 -> 61900 | K9: =IFERROR(J9/C9,0) -> 0.30680016 | L9: =32% -> 0.32 | M9: =K9-L9 -> -0.013199841 | N9: =RawData!N9-RawData!M9 -> -350 | O9: =IFERROR(N9/RawData!M9,0) -> -0.0090206186 | P9: =IFERROR(RawData!L9/C9,0) -> 0.014001784 | Q9: =IFERROR(C9/RawData!O9,0) -> 12.009524
A10: =RawData!A10 -> 46082 | B10: =RawData!B10 -> Outlet C | C10: =RawData!F10 -> 210540 | D10: =RawData!E10 -> 205000 | E10: 66000 | F10: 2948 | G10: 17400 | H10: =C10-D10 -> 5540 | I10: =IFERROR(H10/D10,0) -> 0.02702439 | J10: =RawData!G10+RawData!H10+RawData!I10-RawData!J10-RawData!K10 -> 64800 | K10: =IFERROR(J10/C10,0) -> 0.30777999 | L10: =32% -> 0.32 | M10: =K10-L10 -> -0.012220006 | N10: =RawData!N10-RawData!M10 -> -360 | O10: =IFERROR(N10/RawData!M10,0) -> -0.0089552239 | P10: =IFERROR(RawData!L10/C10,0) -> 0.01400209 | Q10: =IFERROR(C10/RawData!O10,0) -> 12.1
A11: =RawData!A11 -> 46023 | B11: =RawData!B11 -> Outlet D | C11: =RawData!F11 -> 162350 | D11: =RawData!E11 -> 165000 | E11: 53000 | F11: 3200 | G11: 13700 | H11: =C11-D11 -> -2650 | I11: =IFERROR(H11/D11,0) -> -0.016060606 | J11: =RawData!G11+RawData!H11+RawData!I11-RawData!J11-RawData!K11 -> 51200 | K11: =IFERROR(J11/C11,0) -> 0.31536803 | L11: =32% -> 0.32 | M11: =K11-L11 -> -0.004631968 | N11: =RawData!N11-RawData!M11 -> -650 | O11: =IFERROR(N11/RawData!M11,0) -> -0.020967742 | P11: =IFERROR(RawData!L11/C11,0) -> 0.019710502 | Q11: =IFERROR(C11/RawData!O11,0) -> 11.850365
A12: =RawData!A12 -> 46054 | B12: =RawData!B12 -> Outlet D | C12: =RawData!F12 -> 170820 | D12: =RawData!E12 -> 170000 | E12: 56000 | F12: 3500 | G12: 14400 | H12: =C12-D12 -> 820 | I12: =IFERROR(H12/D12,0) -> 0.0048235294 | J12: =RawData!G12+RawData!H12+RawData!I12-RawData!J12-RawData!K12 -> 54400 | K12: =IFERROR(J12/C12,0) -> 0.31846388 | L12: =32% -> 0.32 | M12: =K12-L12 -> -0.0015361199 | N12: =RawData!N12-RawData!M12 -> -720 | O12: =IFERROR(N12/RawData!M12,0) -> -0.021818182 | P12: =IFERROR(RawData!L12/C12,0) -> 0.020489404 | Q12: =IFERROR(C12/RawData!O12,0) -> 11.8625
A13: =RawData!A13 -> 46082 | B13: =RawData!B13 -> Outlet D | C13: =RawData!F13 -> 186540 | D13: =RawData!E13 -> 175000 | E13: 62000 | F13: 5037 | G13: 15300 | H13: =C13-D13 -> 11540 | I13: =IFERROR(H13/D13,0) -> 0.065942857 | J13: =RawData!G13+RawData!H13+RawData!I13-RawData!J13-RawData!K13 -> 60600 | K13: =IFERROR(J13/C13,0) -> 0.3248633 | L13: =32% -> 0.32 | M13: =K13-L13 -> 0.0048633001 | N13: =RawData!N13-RawData!M13 -> -725 | O13: =IFERROR(N13/RawData!M13,0) -> -0.021014493 | P13: =IFERROR(RawData!L13/C13,0) -> 0.027002252 | Q13: =IFERROR(C13/RawData!O13,0) -> 12.192157
... A16: =RawData!A16 -> 46082 | B16: =RawData!B16 -> Outlet E | C16: =RawData!F16 -> 195460 | D16: =RawData!E16 -> 190000 | E16: 61000 | F16: 2140 | G16: 16000 | H16: =C16-D16 -> 5460 | I16: =IFERROR(H16/D16,0) -> 0.028736842 | J16: =RawData!G16+RawData!H16+RawData!I16-RawData!J16-RawData!K16 -> 59900 | K16: =IFERROR(J16/C16,0) -> 0.30645656 | L16: =32% -> 0.32 | M16: =K16-L16 -> -0.013543436 | N16: =RawData!N16-RawData!M16 -> -250 | O16: =IFERROR(N16/RawData!M16,0) -> -0.0069060773 | P16: =IFERROR(RawData!L16/C16,0) -> 0.010948532 | Q16: =IFERROR(C16/RawData!O16,0) -> 12.21625

Sheet Pivot Table
A3: Total Sales
A4: 2652380 | B4: =GETPIVOTDATA("Actual Sales (RM)",$A$3) -> 2652380
A6: Total Food Cost
A7: 836600 | B7: =GETPIVOTDATA("COGS / Stock Usage (RM)",$A$6) -> 836600
A9: Total Purchases
A10: 857500 | B10: =GETPIVOTDATA("Purchases (RM)",$A$9) -> 857500
A12: Stock Variance
A13: -7375 | B13: =GETPIVOTDATA("Stock Variance (RM)",$A$12) -> -7375
A15: Wastage
A16: 43431 | B16: =GETPIVOTDATA("Wastage Cost (RM)",$A$15) -> 43431
A18: Total Transactions
A19: 224250 | B19: =GETPIVOTDATA("Transactions",$A$18) -> 224250
A22: Total Sales | B22: Month
A23: Outlet | B23: Jan | C23: Feb | D23: Mar
A24: Outlet A | B24: 152000 | C24: 160420 | D24: 180450
A25: Outlet B | B25: 158000 | C25: 160420 | D25: 165230
A26: Outlet C | B26: 189550 | C26: 201760 | D26: 210540
A27: Outlet D | B27: 162350 | C27: 170820 | D27: 186540
A28: Outlet E | B28: 172300 | C28: 186540 | D28: 195460
A31: Food Cost % | B31: Month
A32: Outlet | B32: Outlet A | C32: Outlet B | D32: Outlet C | E32: Outlet D | F32: Outlet E
A33: Jan | B33: 0.32368421 | C33: 0.31962025 | D33: 0.31601161 | E33: 0.31536803 | F33: 0.3116657
A34: Feb | B34: 0.32290238 | C34: 0.31479865 | D34: 0.30680016 | E34: 0.31846388 | F34: 0.30234802
A35: Mar | B35: 0.30479357 | C35: 0.34376324 | D35: 0.30777999 | E35: 0.3248633 | F35: 0.30645656
A40: Outlet | B40: Total Sales
A41: Outlet A | B41: 0.18582179
A42: Outlet B | B42: 0.18234567
A43: Outlet C | B43: 0.22690942
A44: Outlet D | B44: 0.195941
A45: Outlet E | B45: 0.20898212
A48: Outlet | B48: Sales | C48: Purchases | D48: Usage
A49: Outlet A | B49: 492870 | C49: 161500 | D49: 156000
A50: Outlet B | B50: 483650 | C50: 160000 | D50: 157800
A51: Outlet C | B51: 601850 | C51: 191000 | D51: 186600
A52: Outlet D | B52: 519710 | C52: 171000 | D52: 166200
A53: Outlet E | B53: 554300 | C53: 174000 | D53: 170000
A56: Outlet | B56: Total Sales | C56: Food Cost % | D56: Food Cost Target % | E56: Food Cost Variance
A57: Outlet C | B57: 601850 | C57: 0.31019725 | D57: 0.32 | E57: -0.029408241
A58: Outlet E | B58: 554300 | C58: 0.30682343 | D58: 0.32 | E58: -0.039529715
A59: Outlet D | B59: 519710 | C59: 0.31956507 | D59: 0.32 | E59: -0.0013047878
...

Sheet Dashboard
E18: Top & Bottom Performers
E20: Outlet | F20: Sales | G20: Food Cost | H20: Target | I20: Variance
E21: ='Pivot Table'!A57 -> Outlet C | F21: ='Pivot Table'!B57 -> 601850 | G21: ='Pivot Table'!C57 -> 0.31019725 | H21: ='Pivot Table'!D57 -> 0.32 | I21: =ABS(G21-H21) -> 0.0098027469
E22: ='Pivot Table'!A58 -> Outlet E | F22: ='Pivot Table'!B58 -> 554300 | G22: ='Pivot Table'!C58 -> 0.30682343 | H22: ='Pivot Table'!D58 -> 0.32 | I22: =ABS(G22-H22) -> 0.013176572
E23: ='Pivot Table'!A59 -> Outlet D | F23: ='Pivot Table'!B59 -> 519710 | G23: ='Pivot Table'!C59 -> 0.31956507 | H23: ='Pivot Table'!D59 -> 0.32 | I23: =ABS(G23-H23) -> 0.00043492926
E24: ='Pivot Table'!A60 -> Outlet A | F24: ='Pivot Table'!B60 -> 492870 | G24: ='Pivot Table'!C60 -> 0.31712672 | H24: ='Pivot Table'!D60 -> 0.32 | I24: =ABS(G24-H24) -> 0.0028732789
E25: ='Pivot Table'!A61 -> Outlet B | F25: ='Pivot Table'!B61 -> 483650 | G25: ='Pivot Table'!C61 -> 0.32606072 | H25: ='Pivot Table'!D61 -> 0.32 | I25: =G25-H25 -> 0.0060607153
E27: Sales Variance
E28: Outlet | F28: Actual | G28: Target | H28: Variance
E29: ='Pivot Table'!A65 -> Outlet B | F29: ='Pivot Table'!B65 -> 483650 | G29: ='Pivot Table'!C65 -> 540000 | H29: ='Pivot Table'!D65 -> -56350
E30: ='Pivot Table'!A66 -> Outlet A | F30: ='Pivot Table'!B66 -> 492870 | G30: ='Pivot Table'!C66 -> 490000 | H30: ='Pivot Table'!D66 -> 2870
E31: ='Pivot Table'!A67 -> Outlet C | F31: ='Pivot Table'!B67 -> 601850 | G31: ='Pivot Table'!C67 -> 595000 | H31: ='Pivot Table'!D67 -> 6850

Sheet Read Me
A1: Purpose | B1: Use this workbook to practise a multi-outlet F&B performance dashboard for an interview.
A2: Important | B2: All values are fictional practice data, not actual Tiga Budak Gemok data.
A3: RawData | B3: One row represents one outlet in one month. Convert/add data here.
A4: Calculations | B4: Contains example formulas for sales variance, COGS/stock usage, food cost %, stock variance, wastage % and average transaction value.
A5: COGS / Stock Usage | B5: Opening Stock + Purchases + Transfer In − Transfer Out − Closing Stock. Make sure transfers and adjustments are recorded consistently.
A6: Stock Variance | B6: Physical Stock Value − System Stock Value. Positive means physical stock is higher under this convention; negative means physical stock is lower.
A7: Food Cost % | B7: COGS / Actual Sales. Format as Percentage.
A8: Food Cost Variance | B8: Actual Food Cost % − Target Food Cost %. A positive result means actual food cost is above target.
A9: Sales Variance | B9: Actual Sales − Budget Sales. A negative result means sales are below budget.
A10: Wastage % | B10: Wastage Cost / Actual Sales. This is a simple practice metric; a business may define its own denominator.
A11: Dashboard build | B11: Create PivotTables from RawData or Calculations, then PivotCharts and slicers for Month, Outlet, Region and Outlet Type.
A12: Slicers | B12: Insert → Slicer, then use Report Connections to connect slicers to relevant PivotTables.
A13: Excel note | B13: If formulas do not calculate immediately, set Formulas → Calculation Options → Automatic, then recalculate.
